Workbook

Sheet Nifty50 PE Analysis
A1: Year | B1: Jan | C1: Feb | D1: Mar | E1: Apr | F1: May | G1: Jun | H1: Jul | I1: Aug | J1: Sep | K1: Oct | L1: Nov | M1: Dec
A2: 2000 | B2: 26.16 | C2: 27.12 | D2: 25.69 | E2: 22.81 | F2: 20.33 | G2: 23.68 | H2: 22.33 | I2: 20.53 | J2: 20.84 | K2: 18.22 | L2: 18.77 | M2: 19.59 | O2: {=SUM(B2:M2/12)} -> 22.1725
A3: 2001 | B3: 20.75 | C3: 21.32 | D3: 18.2 | E3: 16.08 | F3: 15.74 | G3: 15.37 | H3: 15.32 | I3: 15.23 | J3: 13.65 | K3: 13.76 | L3: 14.86 | M3: 15.59 | O3: {=SUM(B3:M3/12)} -> 16.3225
A4: 2002 | B4: 16.42 | C4: 18.32 | D4: 18.59 | E4: 18.02 | F4: 17.44 | G4: 16.28 | H4: 15.39 | I4: 14.54 | J4: 14.69 | K4: 14.25 | L4: 14.55 | M4: 14.57 | O4: {=SUM(B4:M4/12)} -> 16.088333 | P4: 17.09
A5: 2003 | B5: 14.56 | C5: 14.32 | D5: 13.85 | E5: 13.2 | F5: 11.15 | G5: 12.2 | H5: 12.5 | I5: 13.89 | J5: 15.09 | K5: 16.6 | L5: 17.42 | M5: 19.19 | O5: {=SUM(B5:M5/12)} -> 14.4975
A6: 2004 | B6: 21.02 | C6: 20.32 | D6: 20.78 | E6: 19.91 | F6: 14.86 | G6: 12.18 | H6: 13.08 | I6: 13.5 | J6: 14.14 | K6: 15 | L6: 15.67 | M6: 16.04 | O6: {=SUM(B6:M6/12)} -> 16.375
A7: 2005 | B7: 14.41 | C7: 14.4 | D7: 14.98 | E7: 14.16 | F7: 13.77 | G7: 14.01 | H7: 14.31 | I7: 14.61 | J7: 15.58 | K7: 15.26 | L7: 15.47 | M7: 16.72 | O7: {=SUM(B7:M7/12)} -> 14.806667
A8: 2006 | B8: 17.27 | C8: 17.97 | D8: 19.25 | E8: 20.59 | F8: 19.53 | G8: 16.65 | H8: 17.95 | I8: 18.55 | J8: 20.09 | K8: 20.92 | L8: 20.72 | M8: 20.95 | O8: {=SUM(B8:M8/12)} -> 19.203333
A9: 2007 | B9: 21.24 | C9: 19.64 | D9: 17.95 | E9: 19.28 | F9: 19.74 | G9: 20.08 | H9: 21.3 | I9: 19.47 | J9: 21.05 | K9: 24.59 | L9: 25.15 | M9: 26.55 | O9: {=SUM(B9:M9/12)} -> 21.336667 | P9: 18.51
A10: 2008 | B10: 25.33 | C10: 22.19 | D10: 20.58 | E10: 21.26 | F10: 21.46 | G10: 19.04 | H10: 17.56 | I10: 18.63 | J10: 17.98 | K10: 13.77 | L10: 12.42 | M10: 12.69 | O10: {=SUM(B10:M10/12)} -> 18.575833
A11: 2009 | B11: 12.73 | C11: 13.38 | D11: 13.3 | E11: 15.89 | F11: 18.67 | G11: 20.16 | H11: 19.83 | I11: 20.5 | J11: 21.86 | K11: 22.34 | L11: 21.91 | M11: 22.7 | O11: {=SUM(B11:M11/12)} -> 18.605833
A12: 2010 | B12: 22.84 | C12: 20.72 | D12: 22.03 | E12: 22.76 | F12: 21.2 | G12: 21.73 | H12: 22.42 | I12: 22.95 | J12: 24.51 | K12: 25.23 | L12: 24.39 | M12: 23.82 | O12: {=SUM(B12:M12/12)} -> 22.883333
A13: 2011 | B13: 22.84 | C13: 20.67 | D13: 21.16 | E13: 22.02 | F13: 20.37 | G13: 20.2 | H13: 20.49 | I13: 18.29 | J13: 18.11 | K13: 18.15 | L13: 18.11 | M13: 17.32 | O13: {=SUM(B13:M13/12)} -> 19.810833
A14: 2012 | B14: 17.71 | C14: 19.09 | D14: 18.74 | E14: 18.46 | F14: 16.97 | G14: 16.89 | H14: 17.22 | I14: 17.67 | J14: 18.42 | K14: 18.95 | L14: 18.14 | M14: 18.63 | O14: {=SUM(B14:M14/12)} -> 18.074167 | P14: 19.68
A15: 2013 | B15: 18.87 | C15: 18.26 | D15: 17.89 | E15: 17.4 | F15: 18.13 | G15: 17.49 | H15: 17.88 | I15: 16.12 | J15: 16.83 | K15: 17.72 | L15: 17.8 | M15: 18.56 | O15: {=SUM(B15:M15/12)} -> 17.745833
A16: 2014 | B16: 18.29 | C16: 17.37 | D16: 18.33 | E16: 18.99 | F16: 19.62 | G16: 20.57 | H16: 20.66 | I16: 20.42 | J16: 21.2 | K16: 20.65 | L16: 21.5 | M16: 21.23 | O16: {=SUM(B16:M16/12)} -> 19.9025
A17: 2015 | B17: 21.73 | C17: 23.09 | D17: 23.21 | E17: 22.88 | F17: 22.4 | G17: 22.7 | H17: 23.49 | I17: 22.99 | J17: 21.69 | K17: 22.48 | L17: 21.36 | M17: 21.1 | O17: {=SUM(B17:M17/12)} -> 22.426667
A18: 2016 | B18: 20.34 | C18: 19.34 | D18: 20.39 | E18: 21.29 | F18: 21.51 | G18: 22.52 | H18: 23.33 | I18: 23.65 | J18: 24.08 | K18: 23.35 | L18: 21.99 | M18: 21.49 | O18: {=SUM(B18:M18/12)} -> 21.94
A19: 2017 | B19: 22.44 | C19: 23.23 | D19: 23.47 | E19: 23.37 | F19: 24.25 | G19: 24.31 | H19: 25.1 | I19: 25.37 | J19: 25.99 | K19: 26.26 | L19: 26.35 | M19: 26.42 | O19: {=SUM(B19:M19/12)} -> 24.713333 | P19: 24.64
A20: 2018 | B20: 27.24 | C20: 25.61 | D20: 24.97 | E20: 26 | F20: 26.58 | G20: 26.77 | H20: 27.19 | I20: 28.22 | J20: 27.46 | K20: 25.05 | L20: 25.59 | M20: 26.07 | O20: {=SUM(B20:M20/12)} -> 26.395833
A21: 2019 | B21: 26.08 | C21: 26.66 | D21: 27.76 | E21: 29.12 | F21: 28.88 | G21: 29.25 | H21: 28.28 | I21: 27.12 | J21: 26.93 | K21: 26.51 | L21: 27.67 | M21: 28.18 | O21: {=SUM(B21:M21/12)} -> 27.703333
A22: 2020 | B22: 27.96 | C22: 26.92 | D22: 21.38 | E22: 20.38 | F22: 21.24 | G22: 24.7 | H22: 28.6 | I22: 31.59 | J22: 32.55 | K22: 33.99 | L22: 34.34 | M22: 37.26 | O22: {=SUM(B22:M22/12)} -> 28.409167 | Q22: 24.44
A23: 2021 | B23: 38.9 | C23: 40.8 | D23: 40.43 | E23: 32.73 | F23: 29.27 | G23: 29.08 | H23: 28.11 | I23: 26.11 | J23: 26.98 | K23: 27.31 | L23: 23.43 | M23: 23.69 | O23: {=SUM(B23:M23/12)} -> 30.57
A24: 2022 | B24: 23.42 | C24: 22.54 | D24: 21.7 | E24: 22.7 | F24: 20.32 | G24: 19.5 | H24: 20.73 | I24: 21.2 | J24: 20.64 | K24: 21 | L24: 21.9 | M24: 22 | O24: {=SUM(B24:M24/12)} -> 21.470833 | P24: 25.26
A25: 2023 | B25: 21.49 | C25: 20.89 | D25: 20.29 | E25: 20.7 | F25: 21..56 | G25: 21.8 | H25: 23.35 | I25: 22.43 | J25: 22.39 | K25: 21.74 | L25: 21 | M25: 22.61 | O25: =SUM(B26:M26)/12 -> 22.679167
A26: 2024 | B26: 22.86 | C26: 22.66 | D26: 22.52 | E26: 23 | F26: 21.56 | G26: 22.18 | H26: 23.22 | I26: 22.86 | J26: 24.26 | K26: 23.24 | L26: 21.49 | M26: 22.3 | O26: {=SUM(B26:M26/12)} -> 22.679167
A27: 2025 | B27: 21.43 | C27: 20.69 | D27: 20.33 | E27: 21.34 | F27: 22.18 | G27: 22.57
B29: =SUM(B2:B27)/26 -> 21.705 | C29: =SUM(C2:C27)/26 -> 21.443077 | D29: =SUM(D2:D27)/26 -> 21.068077 | E29: =SUM(E2:E27)/26 -> 20.936154 | F29: =SUM(F2:F27)/26 -> 19.506538 | G29: =SUM(G2:G27)/26 -> 20.458077 | H29: =SUM(H2:H27)/25 -> 20.7856 | I29: =SUM(I2:I27)/25 -> 20.6576 | J29: =SUM(J2:J27)/25 -> 21.0804 | K29: =SUM(K2:K27)/25 -> 21.0536 | L29: =SUM(L2:L27)/25 -> 20.88 | M29: =SUM(M2:M27)/25 -> 21.4108 | N29: =SUM(B29:M29)/12 -> 20.91541 | O29: 21.02

Sheet EVI 2025
A1: S.no | B1: Date | C1: Market Cap | D1: US $ | E1: USD/INR | F1: Trillion | G1: Market Cap to GDP | H1: BEER | I1: Nifty 50 Earning Yield | J1: NIFTY 50 EPS | K1: India 10Yr Yield | L1: Nifty 50 | M1: Price to Book | N1: Equity Earnings Yield vs 10 Year G Sec Yield Gap | O1: Nifty 50 pe | P1: US 10yr Bond | Q1: India yr- US 10yr | R1: Dollar index | S1: PREITY Ratio | T1: 91 day T Bill | U1: Nifty Midcap 150 | V1: Midcap 150 PE | W1: Midcap EPS | X1: Midcap Earning Yield | Y1: Nifty Smallcap 250 | Z1: Smallcap 250 PE | AA1: Smallcap EPS | AB1: Smallcap Earning Yield | AC1: Updated: | AD1: 46108
A2: 1 | B2: 44564 | C2: 26941905 | D2: =C2/E2 -> 362122.38 | E2: 74.4 | F2: =D2/100000 -> 3.6212238 | G2: =(F2/DataSheet!$C$9*100) -> 114.33265 | H2: =K2/I2 -> 1.582054 | I2: =(J2/L2)*100 -> 4.0832993 | J2: =L2/O2 -> 719.71009 | K2: 6.46 | L2: 17625.7 | M2: 4.44 | N2: =K2-I2 -> 2.3767007 | O2: 24.49 | P2: 1.637 | Q2: =K2-P2 -> 4.823 | R2: 96.211 | S2: =(O2*T2) -> 87.9191 | T2: 3.59 | U2: 11673.45 | V2: 30.88 | W2: =U2/V2 -> 378.02623 | X2: =(W2/U2)*100 -> 3.238342 | Y2: 9966.35 | Z2: 31.44 | AA2: =Y2/Z2 -> 316.99587 | AB2: =(AA2/Y2)*100 -> 3.1806616
A3: 2 | B3: 44565 | C3: 27136807 | D3: =C3/E3 -> 364105.82 | E3: 74.53 | F3: =D3/100000 -> 3.6410582 | G3: =(F3/DataSheet!$C$9*100) -> 114.95888 | H3: =K3/I3 -> 1.6125532 | I3: =(J3/L3)*100 -> 4.0420372 | J3: =L3/O3 -> 719.69483 | K3: 6.518 | L3: 17805.25 | M3: 4.49 | N3: =K3-I3 -> 2.4759628 | O3: 24.74 | P3: 1.649 | Q3: =K3-P3 -> 4.869 | R3: 96.274 | S3: =(O3*T3) -> 89.064 | T3: 3.6 | U3: 11702.1 | V3: 30.96 | W3: =U3/V3 -> 377.97481 | X3: =(W3/U3)*100 -> 3.2299742 | Y3: 10018.45 | Z3: 31.61 | AA3: =Y3/Z3 -> 316.93926 | AB3: =(AA3/Y3)*100 -> 3.1635558
A4: 3 | B4: 44566 | C4: 27008660 | D4: =C4/E4 -> 363581.61 | E4: 74.285 | F4: =D4/100000 -> 3.6358161 | G4: =(F4/DataSheet!$C$9*100) -> 114.79337 | H4: =K4/I4 -> 1.6211428 | I4: =(J4/L4)*100 -> 4.014452 | J4: =L4/O4 -> 719.60056 | K4: 6.508 | L4: 17925.25 | M4: 4.52 | N4: =K4-I4 -> 2.493548 | O4: 24.91 | P4: 1.7 | Q4: =K4-P4 -> 4.808 | R4: 96.182 | S4: =(O4*T4) -> 89.1778 | T4: 3.58 | U4: 11705.05 | V4: 30.97 | W4: =U4/V4 -> 377.94801 | X4: =(W4/U4)*100 -> 3.2289312 | Y4: 10024.3 | Z4: 31.62 | AA4: =Y4/Z4 -> 317.02404 | AB4: =(AA4/Y4)*100 -> 3.1625553
A5: 4 | B5: 44567 | C5: 27117001 | D5: =C5/E5 -> 364549.32 | E5: 74.385 | F5: =D5/100000 -> 3.6454932 | G5: =(F5/DataSheet!$C$9*100) -> 115.09891 | H5: =K5/I5 -> 1.609065 | I5: =(J5/L5)*100 -> 4.05515 | J5: =L5/O5 -> 719.62287 | K5: 6.525 | L5: 17745.9 | M5: 4.47 | N5: =K5-I5 -> 2.46985 | O5: 24.66 | P5: 1.728 | Q5: =K5-P5 -> 4.797 | R5: 96.326 | S5: =(O5*T5) -> 88.0362 | T5: 3.57 | U5: 11698.7 | V5: 30.95 | W5: =U5/V5 -> 377.98708 | X5: =(W5/U5)*100 -> 3.2310178 | Y5: 10034.95 | Z5: 31.66 | AA5: =Y5/Z5 -> 316.95989 | AB5: =(AA5/Y5)*100 -> 3.1585597
A6: 5 | B6: 44568 | C6: 27237049 | D6: =C6/E6 -> 366690.67 | E6: 74.278 | F6: =D6/100000 -> 3.6669067 | G6: =(F6/DataSheet!$C$9*100) -> 115.77499 | H6: =K6/I6 -> 1.619145 | I6: =(J6/L6)*100 -> 4.040404 | J6: =L6/O6 -> 719.70505 | K6: 6.542 | L6: 17812.7 | M6: 4.49 | N6: =K6-I6 -> 2.501596 | O6: 24.75 | P6: 1.765 | Q6: =K6-P6 -> 4.777 | R6: 95.722 | S6: =(O6*T6) -> 89.1 | T6: 3.6 | U6: 11741.95 | V6: 31.06 | W6: =U6/V6 -> 378.04089 | X6: =(W6/U6)*100 -> 3.219575 | Y6: 10076.6 | Z6: 31.79 | AA6: =Y6/Z6 -> 316.97389 | AB6: =(AA6/Y6)*100 -> 3.1456433
A7: 6 | B7: 44571 | C7: 27464164 | D7: =C7/E7 -> 371012 | E7: 74.025 | F7: =D7/100000 -> 3.71012 | G7: =(F7/DataSheet!$C$9*100) -> 117.13937 | H7: =K7/I7 -> 1.648159 | I7: =(J7/L7)*100 -> 3.9984006 | J7: =L7/O7 -> 719.84406 | K7: 6.59 | L7: 18003.3 | M7: 4.54 | N7: =K7-I7 -> 2.5915994 | O7: 25.01 | P7: 1.755 | Q7: =K7-P7 -> 4.835 | R7: 95.99 | S7: =(O7*T7) -> 89.7859 | T7: 3.59 | U7: 11820.4 | V7: 31.27 | W7: =U7/V7 -> 378.01087 | X7: =(W7/U7)*100 -> 3.1979533 | Y7: 10218.3 | Z7: 32.28 | AA7: =Y7/Z7 -> 316.55204 | AB7: =(AA7/Y7)*100 -> 3.0978934
A8: 7 | B8: 44572 | C8: 27523206 | D8: =C8/E8 -> 372857.28 | E8: 73.817 | F8: =D8/100000 -> 3.7285728 | G8: =(F8/DataSheet!$C$9*100) -> 117.72197 | H8: =K8/I8 -> 1.648413 | I8: =(J8/L8)*100 -> 3.9856517 | J8: =L8/O8 -> 719.6393 | K8: 6.57 | L8: 18055.75 | M8: 4.55 | N8: =K8-I8 -> 2.5843483 | O8: 25.09 | P8: 1.746 | Q8: =K8-P8 -> 4.824 | R8: 95.625 | S8: =(O8*T8) -> 89.8222 | T8: 3.58 | U8: 11839.3 | V8: 31.32 | W8: =U8/V8 -> 378.01086 | X8: =(W8/U8)*100 -> 3.192848 | Y8: 10228.8 | Z8: 32.31 | AA8: =Y8/Z8 -> 316.5831 | AB8: =(AA8/Y8)*100 -> 3.095017
A9: 8 | B9: 44573 | C9: 27726856 | D9: =C9/E9 -> 375717.93 | E9: 73.797 | F9: =D9/100000 -> 3.7571793 | G9: =(F9/DataSheet!$C$9*100) -> 118.62517 | H9: =K9/I9 -> 1.668029 | I9: =(J9/L9)*100 -> 3.9525692 | J9: =L9/O9 -> 719.85573 | K9: 6.593 | L9: 18212.35 | M9: 4.59 | N9: =K9-I9 -> 2.6404308 | O9: 25.3 | P9: 1.752 | Q9: =K9-P9 -> 4.841 | R9: 94.901 | S9: =(O9*T9) -> 90.321 | T9: 3.57 | U9: 11980.05 | V9: 31.69 | W9: =U9/V9 -> 378.03881 | X9: =(W9/U9)*100 -> 3.1555696 | Y9: 10292.35 | Z9: 32.51 | AA9: =Y9/Z9 -> 316.59028 | AB9: =(AA9/Y9)*100 -> 3.0759766
A10: 9 | B10: 44574 | C10: 27818875 | D10: =C10/E10 -> 376073.04 | E10: 73.972 | F10: =D10/100000 -> 3.7607304 | G10: =(F10/DataSheet!$C$9*100) -> 118.73729 | H10: =K10/I10 -> 1.6645257 | I10: =(J10/L10)*100 -> 3.9416634 | J10: =L10/O10 -> 719.66102 | K10: 6.561 | L10: 18257.8 | M10: 4.6 | N10: =K10-I10 -> 2.6193366 | O10: 25.37 | P10: 1.701 | Q10: =K10-P10 -> 4.86 | R10: 94.775 | S10: =(O10*T10) -> 90.8246 | T10: 3.58 | U10: 12039.9 | V10: 31.85 | W10: =U10/V10 -> 378.01884 | X10: =(W10/U10)*100 -> 3.1397174 | Y10: 10352.6 | Z10: 32.64 | AA10: =Y10/Z10 -> 317.17525 | AB10: =(AA10/Y10)*100 -> 3.0637255
A11: 10 | B11: 44575 | C11: 27857090 | D11: =C11/E11 -> 375655.24 | E11: 74.156 | F11: =D11/100000 -> 3.7565524 | G11: =(F11/DataSheet!$C$9*100) -> 118.60537 | H11: =K11/I11 -> 1.665246 | I11: =(J11/L11)*100 -> 3.9525692 | J11: =L11/O11 -> 721.57115 | K11: 6.582 | L11: 18255.75 | M11: 4.6 | N11: =K11-I11 -> 2.6294308 | O11: 25.3 | P11: 1.793 | Q11: =K11-P11 -> 4.789 | R11: 95.161 | S11: =(O11*T11) -> 90.827 | T11: 3.59 | U11: 12036.1 | V11: 31.84 | W11: =U11/V11 -> 378.01822 | X11: =(W11/U11)*100 -> 3.1407035 | Y11: 10424 | Z11: 32.87 | AA11: =Y11/Z11 -> 317.12808 | AB11: =(AA11/Y11)*100 -> 3.0422878
A12: 11 | B12: 44578 | C12: 28010582 | D12: =C12/E12 -> 377221.49 | E12: 74.255 | F12: =D12/100000 -> 3.7722149 | G12: =(F12/DataSheet!$C$9*100) -> 119.09988 | H12: =K12/I12 -> 1.6835532 | I12: =(J12/L12)*100 -> 3.9416634 | J12: =L12/O12 -> 721.64367 | K12: 6.636 | L12: 18308.1 | M12: 4.61 | N12: =K12-I12 -> 2.6943366 | O12: 25.37 | P12: 1.809 | Q12: =K12-P12 -> 4.827 | R12: 95.161 | S12: =(O12*T12) -> 91.332 | T12: 3.6 | U12: 12073.15 | V12: 31.92 | W12: =U12/V12 -> 378.23152 | X12: =(W12/U12)*100 -> 3.1328321 | Y12: 10471.85 | Z12: 33.01 | AA12: =Y12/Z12 -> 317.23266 | AB12: =(AA12/Y12)*100 -> 3.029385
A13: 12 | B13: 44579 | C13: 27634598 | D13: =C13/E13 -> 370610.85 | E13: 74.565 | F13: =D13/100000 -> 3.7061085 | G13: =(F13/DataSheet!$C$9*100) -> 117.01271 | H13: =K13/I13 -> 1.65675 | I13: =(J13/L13)*100 -> 4 | J13: =L13/O13 -> 724.522 | K13: 6.627 | L13: 18113.05 | M13: 4.56 | N13: =K13-I13 -> 2.627 | O13: 25 | P13: 1.875 | Q13: =K13-P13 -> 4.752 | R13: 95.723 | S13: =(O13*T13) -> 90 | T13: 3.6 | U13: 11848.7 | V13: 31.32 | W13: =U13/V13 -> 378.31098 | X13: =(W13/U13)*100 -> 3.192848 | Y13: 10257.8 | Z13: 32.34 | AA13: =Y13/Z13 -> 317.18615 | AB13: =(AA13/Y13)*100 -> 3.0921459
... A249: 248 | B249: 44925 | C249: 28323372 | D249: =C249/E249 -> 342441.93 | E249: 82.71 | F249: =D249/100000 -> 3.4244193 | G249: =(F249/DataSheet!$C$9*100) -> 108.11896 | H249: =K249/I249 -> 1.595028 | I249: =(J249/L249)*100 -> 4.5892611 | J249: =L249/O249 -> 830.8995 | K249: 7.32 | L249: 18105.3 | M249: 4.25 | N249: =K249-I249 -> 2.7307389 | O249: 21.79 | P249: 3.87 | Q249: =K249-P249 -> 3.45 | R249: 103.26 | S249: =(O249*T249) -> 138.1486 | T249: 6.34 | U249: 11885.75 | V249: 26.12 | W249: =U249/V249 -> 455.04403 | X249: =(W249/U249)*100 -> 3.8284839 | Y249: 9481.25 | Z249: 19.04 | AA249: =Y249/Z249 -> 497.96481 | AB249: =(AA249/Y249)*100 -> 5.2521008
A250: 249 | B250: 44928 | C250: 28454959 | D250: =C250/E250 -> 343908.14 | E250: 82.74 | F250: =D250/100000 -> 3.4390814 | G250: =(F250/DataSheet!$C$10*100) -> 102.77849 | H250: =K250/I250 -> 1.60746 | I250: =(J250/L250)*100 -> 4.56621 | J250: =L250/O250 -> 830.93379 | K250: 7.34 | L250: 18197.45 | M250: 4.27 | N250: =K250-I250 -> 2.77379 | O250: 21.9 | P250: 3.87 | Q250: =K250-P250 -> 3.47 | R250: 104.41 | S250: =(O250*T250) -> 137.751 | T250: 6.29 | U250: 11970.3 | V250: 26.31 | W250: =U250/V250 -> 454.97149 | X250: =(W250/U250)*100 -> 3.8008362 | Y250: 9552.8 | Z250: 19.18 | AA250: =Y250/Z250 -> 498.06048 | AB250: =(AA250/Y250)*100 -> 5.2137643
A251: 250 | B251: 44929 | C251: 28548826 | D251: =C251/E251 -> 344917.55 | E251: 82.77 | F251: =D251/100000 -> 3.4491755 | G251: =(F251/DataSheet!$C$10*100) -> 103.08016 | H251: =K251/I251 -> 1.606008 | I251: =(J251/L251)*100 -> 4.5578851 | J251: =L251/O251 -> 831.01869 | K251: 7.32 | L251: 18232.55 | M251: 4.28 | N251: =K251-I251 -> 2.7621149 | O251: 21.94 | P251: 3.75 | Q251: =K251-P251 -> 3.57 | R251: 104.31 | S251: =(O251*T251) -> 138.222 | T251: 6.3 | U251: 11994.4 | V251: 26.36 | W251: =U251/V251 -> 455.02276 | X251: =(W251/U251)*100 -> 3.7936267 | Y251: 9566.55 | Z251: 19.21 | AA251: =Y251/Z251 -> 497.99844 | AB251: =(AA251/Y251)*100 -> 5.2056221
A252: 251 | B252: 44930 | C252: 28257666 | D252: =C252/E252 -> 341936.91 | E252: 82.64 | F252: =D252/100000 -> 3.4193691 | G252: =(F252/DataSheet!$C$10*100) -> 102.18938 | H252: =K252/I252 -> 1.589172 | I252: =(J252/L252)*100 -> 4.6061723 | J252: =L252/O252 -> 831.08936 | K252: 7.32 | L252: 18042.95 | M252: 4.23 | N252: =K252-I252 -> 2.7138277 | O252: 21.71 | P252: 3.69 | Q252: =K252-P252 -> 3.63 | R252: 104.02 | S252: =(O252*T252) -> 138.0756 | T252: 6.36 | U252: 11886.95 | V252: 26.12 | W252: =U252/V252 -> 455.08997 | X252: =(W252/U252)*100 -> 3.8284839 | Y252: 9480.9 | Z252: 19.04 | AA252: =Y252/Z252 -> 497.94643 | AB252: =(AA252/Y252)*100 -> 5.2521008
A253: 252 | B253: 44931 | C253: 28279706 | D253: =C253/E253 -> 342535.19 | E253: 82.56 | F253: =D253/100000 -> 3.4253519 | G253: =(F253/DataSheet!$C$10*100) -> 102.36818 | H253: =K253/I253 -> 1.58478 | I253: =(J253/L253)*100 -> 4.6189376 | J253: =L253/O253 -> 831.04619 | K253: 7.32 | L253: 17992.15 | M253: 4.22 | N253: =K253-I253 -> 2.7010624 | O253: 21.65 | P253: 3.72 | Q253: =K253-P253 -> 3.6 | R253: 104.82 | S253: =(O253*T253) -> 137.9105 | T253: 6.37 | U253: 11932.85 | V253: 26.22 | W253: =U253/V253 -> 455.10488 | X253: =(W253/U253)*100 -> 3.8138825 | Y253: 9479.5 | Z253: 19.03 | AA253: =Y253/Z253 -> 498.13452 | AB253: =(AA253/Y253)*100 -> 5.2548607
A254: 253 | B254: 44932 | C254: 28057696 | D254: =C254/E254 -> 341044.08 | E254: 82.27 | F254: =D254/100000 -> 3.4104408 | G254: =(F254/DataSheet!$C$10*100) -> 101.92255 | H254: =K254/I254 -> 1.583813 | I254: =(J254/L254)*100 -> 4.6533271 | J254: =L254/O254 -> 831.05863 | K254: 7.37 | L254: 17859.45 | M254: 4.19 | N254: =K254-I254 -> 2.7166729 | O254: 21.49 | P254: 3.56 | Q254: =K254-P254 -> 3.81 | R254: 103.64 | S254: =(O254*T254) -> 136.8913 | T254: 6.37 | U254: 11850.6 | V254: 26.04 | W254: =U254/V254 -> 455.09217 | X254: =(W254/U254)*100 -> 3.8402458 | Y254: 9406.75 | Z254: 18.89 | AA254: =Y254/Z254 -> 497.97512 | AB254: =(AA254/Y254)*100 -> 5.2938062
A255: 254 | B255: 44935 | C255: 28374278 | D255: =C255/E255 -> 345311.89 | E255: 82.17 | F255: =D255/100000 -> 3.4531189 | G255: =(F255/DataSheet!$C$10*100) -> 103.19801 | H255: =K255/I255 -> 1.598652 | I255: =(J255/L255)*100 -> 4.5913682 | J255: =L255/O255 -> 831.09275 | K255: 7.34 | L255: 18101.2 | M255: 4.25 | N255: =K255-I255 -> 2.7486318 | O255: 21.78 | P255: 3.52 | Q255: =K255-P255 -> 3.82 | R255: 102.73 | S255: =(O255*T255) -> 138.9564 | T255: 6.38 | U255: 11948.9 | V255: 26.26 | W255: =U255/V255 -> 455.02285 | X255: =(W255/U255)*100 -> 3.8080731 | Y255: 9444.15 | Z255: 18.96 | AA255: =Y255/Z255 -> 498.10918 | AB255: =(AA255/Y255)*100 -> 5.2742616
A256: 255 | B256: 44936 | C256: 28164222 | D256: =C256/E256 -> 345149.78 | E256: 81.6 | F256: =D256/100000 -> 3.4514978 | G256: =(F256/DataSheet!$C$10*100) -> 103.14956 | H256: =K256/I256 -> 1.576036 | I256: =(J256/L256)*100 -> 4.6382189 | J256: =L256/O256 -> 830.8975 | K256: 7.31 | L256: 17914.15 | M256: 4.2 | N256: =K256-I256 -> 2.6717811 | O256: 21.56 | P256: 3.61 | Q256: =K256-P256 -> 3.7 | R256: 102.98 | S256: =(O256*T256) -> 137.5528 | T256: 6.38 | U256: 11899.55 | V256: 26.15 | W256: =U256/V256 -> 455.04971 | X256: =(W256/U256)*100 -> 3.8240918 | Y256: 9398 | Z256: 18.87 | AA256: =Y256/Z256 -> 498.03922 | AB256: =(AA256/Y256)*100 -> 5.2994171
A257: 256 | B257: 44937 | C257: 28116864 | D257: =C257/E257 -> 344442.78 | E257: 81.63 | F257: =D257/100000 -> 3.4444278 | G257: =(F257/DataSheet!$C$10*100) -> 102.93827 | H257: =K257/I257 -> 1.568808 | I257: =(J257/L257)*100 -> 4.6468401 | J257: =L257/O257 -> 831.58457 | K257: 7.29 | L257: 17895.7 | M257: 4.2 | N257: =K257-I257 -> 2.6431599 | O257: 21.52 | P257: 3.54 | Q257: =K257-P257 -> 3.75 | R257: 102.92 | S257: =(O257*T257) -> 137.728 | T257: 6.4 | U257: 11862.85 | V257: 26.07 | W257: =U257/V257 -> 455.03836 | X257: =(W257/U257)*100 -> 3.8358266 | Y257: 9403.2 | Z257: 18.88 | AA257: =Y257/Z257 -> 498.05085 | AB257: =(AA257/Y257)*100 -> 5.2966102
A258: 257 | B258: 44938 | C258: 28079395 | D258: =C258/E258 -> 346231.75 | E258: 81.1 | F258: =D258/100000 -> 3.4623175 | G258: =(F258/DataSheet!$C$10*100) -> 103.47291 | H258: =K258/I258 -> 1.563016 | I258: =(J258/L258)*100 -> 4.6576619 | J258: =L258/O258 -> 831.77457 | K258: 7.28 | L258: 17858.2 | M258: 4.19 | N258: =K258-I258 -> 2.6223381 | O258: 21.47 | P258: 3.44 | Q258: =K258-P258 -> 3.84 | R258: 101.99 | S258: =(O258*T258) -> 137.8374 | T258: 6.42 | U258: 11836.4 | V258: 26.01 | W258: =U258/V258 -> 455.07113 | X258: =(W258/U258)*100 -> 3.8446751 | Y258: 9409.4 | Z258: 18.89 | AA258: =Y258/Z258 -> 498.1154 | AB258: =(AA258/Y258)*100 -> 5.2938062
A259: 258 | B259: 44939 | C259: 28213564 | D259: =C259/E259 -> 347115.7 | E259: 81.28 | F259: =D259/100000 -> 3.471157 | G259: =(F259/DataSheet!$C$10*100) -> 103.73709 | H259: =K259/I259 -> 1.570266 | I259: =(J259/L259)*100 -> 4.6425255 | J259: =L259/O259 -> 833.63974 | K259: 7.29 | L259: 17956.6 | M259: 4.21 | N259: =K259-I259 -> 2.6474745 | O259: 21.54 | P259: 3.49 | Q259: =K259-P259 -> 3.8 | R259: 101.94 | S259: =(O259*T259) -> 138.2868 | T259: 6.42 | U259: 11830.4 | V259: 26 | W259: =U259/V259 -> 455.01538 | X259: =(W259/U259)*100 -> 3.8461538 | Y259: 9436.25 | Z259: 18.94 | AA259: =Y259/Z259 -> 498.21806 | AB259: =(AA259/Y259)*100 -> 5.279831
A260: 259 | B260: 44942 | C260: 28147293 | D260: =C260/E260 -> 344857.79 | E260: 81.62 | F260: =D260/100000 -> 3.4485779 | G260: =(F260/DataSheet!$C$10*100) -> 103.0623 | H260: =K260/I260 -> 1.562088 | I260: =(J260/L260)*100 -> 4.6860356 | J260: =L260/O260 -> 838.55904 | K260: 7.32 | L260: 17894.85 | M260: 4.19 | N260: =K260-I260 -> 2.6339644 | O260: 21.34 | P260: 3.52 | Q260: =K260-P260 -> 3.8 | R260: 101.94 | S260: =(O260*T260) -> 137.2162 | T260: 6.43 | U260: 11800.3 | V260: 26.16 | W260: =U260/V260 -> 451.0818 | X260: =(W260/U260)*100 -> 3.82263 | Y260: 9431.25 | Z260: 18.93 | AA260: =Y260/Z260 -> 498.21712 | AB260: =(AA260/Y260)*100 -> 5.2826202
A261: 260 | B261: 44943 | C261: 28272805 | D261: =C261/E261 -> 346353.11 | E261: 81.63 | F261: =D261/100000 -> 3.4635311 | G261: =(F261/DataSheet!$C$10*100) -> 103.50918 | H261: =K261/I261 -> 1.578149 | I261: =(J261/L261)*100 -> 4.6446818 | J261: =L261/O261 -> 838.51835 | K261: 7.33 | L261: 18053.3 | M261: 4.23 | N261: =K261-I261 -> 2.6853182 | O261: 21.53 | P261: 3.54 | Q261: =K261-P261 -> 3.79 | R261: 102.14 | S261: =(O261*T261) -> 138.4379 | T261: 6.43 | U261: 11793.6 | V261: 26.03 | W261: =U261/V261 -> 453.07722 | X261: =(W261/U261)*100 -> 3.8417211 | Y261: 9417.95 | Z261: 18.87 | AA261: =Y261/Z261 -> 499.09645 | AB261: =(AA261/Y261)*100 -> 5.2994171
... A495: 494 | B495: 45289 | C495: 36937726 | D495: =C495/E495 -> 444016.42 | E495: 83.19 | F495: =D495/100000 -> 4.4401642 | G495: =(F495/DataSheet!$C$10*100) -> 132.6963 | H495: =K495/I495 -> 1.661289 | I495: =(J495/L495)*100 -> 4.3159258 | J495: =L495/O495 -> 937.91109 | K495: 7.17 | L495: 21731.4 | M495: 3.81 | N495: =K495-I495 -> 2.8540742 | O495: 23.17 | P495: 3.86 | Q495: =K495-P495 -> 3.31 | R495: 101.02 | S495: =(O495*T495) -> 159.873 | T495: 6.9 | U495: 17077.05 | V495: 26.51 | W495: =U495/V495 -> 644.1739 | X495: =(W495/U495)*100 -> 3.7721614 | Y495: 14041.3 | Z495: 27.37 | AA495: =Y495/Z495 -> 513.0179 | AB495: =(AA495/Y495)*100 -> 3.6536354
A496: 495 | B496: 45292 | C496: 37094900 | D496: =C496/E496 -> 445691.46 | E496: 83.23 | F496: =D496/100000 -> 4.4569146 | G496: =(F496/DataSheet!$C$11*100) -> 122.49352 | H496: =K496/I496 -> 1.666642 | I496: =(J496/L496)*100 -> 4.3140638 | J496: =L496/O496 -> 937.95945 | K496: 7.19 | L496: 21741.9 | M496: 3.81 | N496: =K496-I496 -> 2.8759362 | O496: 23.18 | P496: 3.89 | Q496: =K496-P496 -> 3.3 | R496: 101.02 | S496: =(O496*T496) -> 160.8692 | T496: 6.94 | U496: 17174 | V496: 26.66 | W496: =U496/V496 -> 644.18605 | X496: =(W496/U496)*100 -> 3.7509377 | Y496: 14129.7 | Z496: 27.54 | AA496: =Y496/Z496 -> 513.061 | AB496: =(AA496/Y496)*100 -> 3.6310821
A497: 496 | B497: 45293 | C497: 37029724 | D497: =C497/E497 -> 444694.65 | E497: 83.27 | F497: =D497/100000 -> 4.4469465 | G497: =(F497/DataSheet!$C$11*100) -> 122.21956 | H497: =K497/I497 -> 1.6632 | I497: =(J497/L497)*100 -> 4.3290043 | J497: =L497/O497 -> 937.91342 | K497: 7.2 | L497: 21665.8 | M497: 3.79 | N497: =K497-I497 -> 2.8709957 | O497: 23.1 | P497: 3.94 | Q497: =K497-P497 -> 3.26 | R497: 101.89 | S497: =(O497*T497) -> 160.083 | T497: 6.93 | U497: 17148.1 | V497: 26.62 | W497: =U497/V497 -> 644.18107 | X497: =(W497/U497)*100 -> 3.756574 | Y497: 14124.25 | Z497: 27.53 | AA497: =Y497/Z497 -> 513.0494 | AB497: =(AA497/Y497)*100 -> 3.632401
A498: 497 | B498: 45294 | C498: 37019529 | D498: =C498/E498 -> 444518.84 | E498: 83.28 | F498: =D498/100000 -> 4.4451884 | G498: =(F498/DataSheet!$C$11*100) -> 122.17124 | H498: =K498/I498 -> 1.653974 | I498: =(J498/L498)*100 -> 4.3591979 | J498: =L498/O498 -> 937.98387 | K498: 7.21 | L498: 21517.35 | M498: 3.77 | N498: =K498-I498 -> 2.8508021 | O498: 22.94 | P498: 3.92 | Q498: =K498-P498 -> 3.29 | R498: 102.19 | S498: =(O498*T498) -> 158.9742 | T498: 6.93 | U498: 17189.95 | V498: 26.68 | W498: =U498/V498 -> 644.30097 | X498: =(W498/U498)*100 -> 3.7481259 | Y498: 14141 | Z498: 27.57 | AA498: =Y498/Z498 -> 512.91259 | AB498: =(AA498/Y498)*100 -> 3.6271309
A499: 498 | B499: 45295 | C499: 37346699 | D499: =C499/E499 -> 448662.89 | E499: 83.24 | F499: =D499/100000 -> 4.4866289 | G499: =(F499/DataSheet!$C$11*100) -> 123.31019 | H499: =K499/I499 -> 1.667098 | I499: =(J499/L499)*100 -> 4.3308792 | J499: =L499/O499 -> 938.0078 | K499: 7.22 | L499: 21658.6 | M499: 3.79 | N499: =K499-I499 -> 2.8891208 | O499: 23.09 | P499: 4 | Q499: =K499-P499 -> 3.22 | R499: 102.13 | S499: =(O499*T499) -> 160.7064 | T499: 6.96 | U499: 17443.75 | V499: 27.07 | W499: =U499/V499 -> 644.39416 | X499: =(W499/U499)*100 -> 3.6941263 | Y499: 14286.3 | Z499: 27.85 | AA499: =Y499/Z499 -> 512.97307 | AB499: =(AA499/Y499)*100 -> 3.5906643
A500: 499 | B500: 45296 | C500: 37448192 | D500: =C500/E500 -> 450640.1 | E500: 83.1 | F500: =D500/100000 -> 4.506401 | G500: =(F500/DataSheet!$C$11*100) -> 123.8536 | H500: =K500/I500 -> 1.673745 | I500: =(J500/L500)*100 -> 4.3196544 | J500: =L500/O500 -> 937.83153 | K500: 7.23 | L500: 21710.8 | M500: 3.8 | N500: =K500-I500 -> 2.9103456 | O500: 23.15 | P500: 4.05 | Q500: =K500-P500 -> 3.18 | R500: 102.12 | S500: =(O500*T500) -> 160.4295 | T500: 6.93 | U500: 17499.65 | V500: 27.16 | W500: =U500/V500 -> 644.31701 | X500: =(W500/U500)*100 -> 3.6818851 | Y500: 14382.4 | Z500: 28.04 | AA500: =Y500/Z500 -> 512.92439 | AB500: =(AA500/Y500)*100 -> 3.5663338
A501: 500 | B501: 45299 | C501: 37150869 | D501: =C501/E501 -> 447385.22 | E501: 83.04 | F501: =D501/100000 -> 4.4738522 | G501: =(F501/DataSheet!$C$11*100) -> 122.95903 | H501: =K501/I501 -> 1.65168 | I501: =(J501/L501)*100 -> 4.3591979 | J501: =L501/O501 -> 937.79425 | K501: 7.2 | L501: 21513 | M501: 3.77 | N501: =K501-I501 -> 2.8408021 | O501: 22.94 | P501: 4.02 | Q501: =K501-P501 -> 3.18 | R501: 101.92 | S501: =(O501*T501) -> 159.433 | T501: 6.95 | U501: 17350.55 | V501: 26.93 | W501: =U501/V501 -> 644.28333 | X501: =(W501/U501)*100 -> 3.7133309 | Y501: 14298.2 | Z501: 27.87 | AA501: =Y501/Z501 -> 513.03193 | AB501: =(AA501/Y501)*100 -> 3.5880875
A502: 501 | B502: 45300 | C502: 37265203 | D502: =C502/E502 -> 448438.06 | E502: 83.1 | F502: =D502/100000 -> 4.4843806 | G502: =(F502/DataSheet!$C$11*100) -> 123.2484 | H502: =K502/I502 -> 1.649246 | I502: =(J502/L502)*100 -> 4.3535046 | J502: =L502/O502 -> 937.95603 | K502: 7.18 | L502: 21544.85 | M502: 3.77 | N502: =K502-I502 -> 2.8264954 | O502: 22.97 | P502: 4.01 | Q502: =K502-P502 -> 3.17 | R502: 102.28 | S502: =(O502*T502) -> 159.8712 | T502: 6.96 | U502: 17382 | V502: 26.98 | W502: =U502/V502 -> 644.255 | X502: =(W502/U502)*100 -> 3.7064492 | Y502: 14350.9 | Z502: 27.97 | AA502: =Y502/Z502 -> 513.08187 | AB502: =(AA502/Y502)*100 -> 3.5752592
A503: 502 | B503: 45301 | C503: 37392677 | D503: =C503/E503 -> 450405.65 | E503: 83.02 | F503: =D503/100000 -> 4.5040565 | G503: =(F503/DataSheet!$C$11*100) -> 123.78917 | H503: =K503/I503 -> 1.652685 | I503: =(J503/L503)*100 -> 4.3383948 | J503: =L503/O503 -> 937.90456 | K503: 7.17 | L503: 21618.7 | M503: 3.79 | N503: =K503-I503 -> 2.8316052 | O503: 23.05 | P503: 4.03 | Q503: =K503-P503 -> 3.14 | R503: 102.08 | S503: =(O503*T503) -> 160.428 | T503: 6.96 | U503: 17425.35 | V503: 27.05 | W503: =U503/V503 -> 644.19039 | X503: =(W503/U503)*100 -> 3.6968577 | Y503: 14379.85 | Z503: 28.03 | AA503: =Y503/Z503 -> 513.01641 | AB503: =(AA503/Y503)*100 -> 3.5676061
A504: 503 | B504: 45302 | C504: 37565219 | D504: =C504/E504 -> 452266.06 | E504: 83.06 | F504: =D504/100000 -> 4.5226606 | G504: =(F504/DataSheet!$C$11*100) -> 124.30048 | H504: =K504/I504 -> 1.652528 | I504: =(J504/L504)*100 -> 4.3327556 | J504: =L504/O504 -> 937.92028 | K504: 7.16 | L504: 21647.2 | M504: 3.79 | N504: =K504-I504 -> 2.8272444 | O504: 23.08 | P504: 3.97 | Q504: =K504-P504 -> 3.19 | R504: 102.02 | S504: =(O504*T504) -> 160.406 | T504: 6.95 | U504: 17500.5 | V504: 27.16 | W504: =U504/V504 -> 644.34831 | X504: =(W504/U504)*100 -> 3.6818851 | Y504: 14498.55 | Z504: 28.28 | AA504: =Y504/Z504 -> 512.67857 | AB504: =(AA504/Y504)*100 -> 3.5360679
A505: 504 | B505: 45303 | C505: 37846544 | D505: =C505/E505 -> 456808.02 | E505: 82.85 | F505: =D505/100000 -> 4.5680802 | G505: =(F505/DataSheet!$C$11*100) -> 125.54879 | H505: =K505/I505 -> 1.673478 | I505: =(J505/L505)*100 -> 4.2844901 | J505: =L505/O505 -> 938.06984 | K505: 7.17 | L505: 21894.55 | M505: 3.83 | N505: =K505-I505 -> 2.8855099 | O505: 23.34 | P505: 3.93 | Q505: =K505-P505 -> 3.24 | R505: 102.15 | S505: =(O505*T505) -> 162.213 | T505: 6.95 | U505: 17563.85 | V505: 27.26 | W505: =U505/V505 -> 644.30851 | X505: =(W505/U505)*100 -> 3.6683786 | Y505: 14552.75 | Z505: 28.39 | AA505: =Y505/Z505 -> 512.60127 | AB505: =(AA505/Y505)*100 -> 3.522367
A506: 505 | B506: 45306 | C506: 38129439 | D506: =C506/E506 -> 460389.27 | E506: 82.82 | F506: =D506/100000 -> 4.6038927 | G506: =(F506/DataSheet!$C$11*100) -> 126.53306 | H506: =K506/I506 -> 1.684326 | I506: =(J506/L506)*100 -> 4.2390844 | J506: =L506/O506 -> 936.72955 | K506: 7.14 | L506: 22097.45 | M506: 3.87 | N506: =K506-I506 -> 2.9009156 | O506: 23.59 | P506: 3.98 | Q506: =K506-P506 -> 3.16 | R506: 102.15 | S506: =(O506*T506) -> 163.9505 | T506: 6.95 | U506: 17656.35 | V506: 27.39 | W506: =U506/V506 -> 644.6276 | X506: =(W506/U506)*100 -> 3.6509675 | Y506: 14589 | Z506: 28.45 | AA506: =Y506/Z506 -> 512.79438 | AB506: =(AA506/Y506)*100 -> 3.5149385
A507: 506 | B507: 45307 | C507: 38021747 | D507: =C507/E507 -> 457652.23 | E507: 83.08 | F507: =D507/100000 -> 4.5765223 | G507: =(F507/DataSheet!$C$11*100) -> 125.78081 | H507: =K507/I507 -> 1.679328 | I507: =(J507/L507)*100 -> 4.2517007 | J507: =L507/O507 -> 936.74745 | K507: 7.14 | L507: 22032.3 | M507: 3.86 | N507: =K507-I507 -> 2.8882993 | O507: 23.52 | P507: 4.05 | Q507: =K507-P507 -> 3.09 | R507: 103.11 | S507: =(O507*T507) -> 163.9344 | T507: 6.97 | U507: 17599.8 | V507: 27.3 | W507: =U507/V507 -> 644.68132 | X507: =(W507/U507)*100 -> 3.6630037 | Y507: 14549.05 | Z507: 28.37 | AA507: =Y507/Z507 -> 512.83222 | AB507: =(AA507/Y507)*100 -> 3.5248502
... A744: 743 | B744: 45657 | C744: 44347671 | D744: =C744/E744 -> 518358.82 | E744: 85.554 | F744: =D744/100000 -> 5.1835882 | G744: =(F744/DataSheet!$C$11*100) -> 142.46537 | H744: =K744/I744 -> 1.4727861 | I744: =(J744/L744)*100 -> 4.5892611 | J744: =L744/O744 -> 1085.1216 | K744: 6.759 | L744: 23644.8 | M744: 3.53 | N744: =K744-I744 -> 2.1697389 | O744: 21.79 | P744: 4.572 | Q744: =K744-P744 -> 2.187 | R744: 108.296 | S744: =(O744*T744) -> 143.3782 | T744: 6.58 | U744: 21141.2 | V744: 43.3 | W744: =U744/V744 -> 488.24942 | X744: =(W744/U744)*100 -> 2.3094688 | Y744: 17752.25 | Z744: 34.39 | AA744: =Y744/Z744 -> 516.20384 | AB744: =(AA744/Y744)*100 -> 2.907822
...

Sheet DataSheet
A1: Calender Year Decemebr | B1: GDP | C1: Trillion | D1: CY Change | E1: Median USDINR | F1: Median MarketCap to GDP | G1: Median BEER Ratio | H1: Median Preity Ratio | I1: Median Nifty Earning Yield | J1: Median Nifty Midcap Earning Yield | K1: Median Nifty Smallcap Yield | L1: Median India 10Year Yield | M1: Median 10 Year US Yield | N1: Median Yield Gap
A2: 2014 | B2: 2040 | C2: =B2/1000 -> 2.04 | E2: =MEDIAN('EVI 2025 Workings'!E2:E1048576) -> 82.915 | F2: =MEDIAN('EVI 2025 Workings'!G2:G1048576) -> 116.50305 | G2: =MEDIAN('EVI 2025 Workings'!H2:H1048576) -> 1.5455035 | H2: =MEDIAN('EVI 2025 Workings'!S2:S1048576) -> 1.4465 | I2: =MEDIAN('EVI 2025 Workings'!I2:I1048576) -> 4.5558087 | J2: =MEDIAN('EVI 2025 Workings'!X2:X1048576) -> 3.7230082 | K2: =MEDIAN('EVI 2025 Workings'!AB2:AB1048576) -> 3.8189816 | L2: =MEDIAN('EVI 2025 Workings'!K2:K1048576) -> 7.09 | M2: =MEDIAN('EVI 2025 Workings'!P2:P1048576) -> 3.98 | N2: =MEDIAN('EVI 2025 Workings'!N2:N1048576) -> 2.5185076
A3: 2015 | B3: 2100 | C3: =B3/1000 -> 2.1 | D3: =((B3-B2)/B2) -> 0.029411765
A4: 2016 | B4: 2294.8 | C4: =B4/1000 -> 2.2948 | D4: =((B4-B3)/B3) -> 0.092761905
A5: 2017 | B5: 2651.47 | C5: =B5/1000 -> 2.65147 | D5: =((B5-B4)/B4) -> 0.15542531
A6: 2018 | B6: 2702.93 | C6: =B6/1000 -> 2.70293 | D6: =((B6-B5)/B5) -> 0.019408102
A7: 2019 | B7: 2835.61 | C7: =B7/1000 -> 2.83561 | D7: =((B7-B6)/B6) -> 0.049087472
A8: 2020 | B8: 2674.85 | C8: =B8/1000 -> 2.67485 | D8: =((B8-B7)/B7) -> -0.056693269
A9: 2021 | B9: 3167.27 | C9: =B9/1000 -> 3.16727 | D9: =((B9-B8)/B8) -> 0.18409257
A10: 2022 | B10: 3346.11 | C10: =B10/1000 -> 3.34611 | D10: =((B10-B9)/B9) -> 0.056465031 | E10: 82.71 | F10: 108.03 | G10: 1.6 | H10: 1.38 | I10: 4.59 | J10: 3.83 | K10: 5.25 | L10: 7.32 | M10: 3.87 | N10: 3.45
A11: 2023 | B11: 3638.49 | C11: =B11/1000 -> 3.63849 | D11: =((B11-B10)/B10) -> 0.087379076 | E11: 83.19 | F11: 132.54 | G11: 1.66 | H11: 1.6 | I11: 4.32 | J11: 3.77 | K11: 3.65 | L11: 7.17 | M11: 3.86 | N11: 3.31
A12: 2024 | B12: 3760.81 | C12: =B12/1000 -> 3.76081 | D12: =((B12-B11)/B11) -> 0.033618342 | E12: 85.55 | F12: 145.2 | G12: 1.47 | H12: 1.43 | I12: 4.59 | J12: 2.31 | K12: 2.91 | L12: 6.76 | M12: 4.57 | N12: 2.19
A13: 2025 | B13: 3956.07 | C13: =B13/1000 -> 3.95607 | D13: =((B13-B12)/B12) -> 0.051919666

Sheet EVI 2025 Workings
A1: S.no | B1: Date | C1: Market Cap | D1: US $ | E1: USD/INR | F1: Trillion | G1: Market Cap to GDP | H1: BEER | I1: Nifty 50 Earning Yield | J1: NIFTY 50 EPS | K1: India 10Yr Yield | L1: Nifty 50 | M1: Price to Book | N1: Yield Gap | O1: Nifty 50 pe | P1: US 10yr Bond | Q1: India yr- US 10yr | R1: Dollar index | S1: PREITY Ratio | T1: 91 day T Bill | U1: Nifty Midcap 150 | V1: Midcap 150 PE | W1: Midcap EPS | X1: Midcap Earning Yield | Y1: Nifty Smallcap 250 | Z1: Smallcap 250 PE | AA1: Smallcap EPS | AB1: Smallcap Earning Yield
A2: 1 | B2: 44564 | C2: 26941905 | D2: =C2/E2 -> 362122.38 | E2: 74.4 | F2: =D2/100000 -> 3.6212238 | G2: =(F2/DataSheet!$C$9*100) -> 114.33265 | H2: =K2/I2 -> 1.582054 | I2: =(J2/L2)*100 -> 4.0832993 | J2: =L2/O2 -> 719.71009 | K2: 6.46 | L2: 17625.7 | M2: 4.44 | N2: =K2-I2 -> 2.3767007 | O2: 24.49 | P2: 1.637 | Q2: =K2-P2 -> 4.823 | R2: 96.211 | S2: =(O2*T2)/100 -> 0.879191 | T2: 3.59 | U2: 30788 | V2: 30.88 | W2: =U2/V2 -> 997.02073 | X2: =(W2/U2)*100 -> 3.238342 | Y2: 9966.35 | Z2: 31.44 | AA2: =Y2/Z2 -> 316.99587 | AB2: =(AA2/Y2)*100 -> 3.1806616
A3: 2 | B3: 44565 | C3: 27136807 | D3: =C3/E3 -> 364105.82 | E3: 74.53 | F3: =D3/100000 -> 3.6410582 | G3: =(F3/DataSheet!$C$9*100) -> 114.95888 | H3: =K3/I3 -> 1.6125532 | I3: =(J3/L3)*100 -> 4.0420372 | J3: =L3/O3 -> 719.69483 | K3: 6.518 | L3: 17805.25 | M3: 4.49 | N3: =K3-I3 -> 2.4759628 | O3: 24.74 | P3: 1.649 | Q3: =K3-P3 -> 4.869 | R3: 96.274 | S3: =(O3*T3)/100 -> 0.89064 | T3: 3.6 | U3: 30870.35 | V3: 30.96 | W3: =U3/V3 -> 997.10433 | X3: =(W3/U3)*100 -> 3.2299742 | Y3: 10018.45 | Z3: 31.61 | AA3: =Y3/Z3 -> 316.93926 | AB3: =(AA3/Y3)*100 -> 3.1635558
A4: 3 | B4: 44566 | C4: 27008660 | D4: =C4/E4 -> 363581.61 | E4: 74.285 | F4: =D4/100000 -> 3.6358161 | G4: =(F4/DataSheet!$C$9*100) -> 114.79337 | H4: =K4/I4 -> 1.6211428 | I4: =(J4/L4)*100 -> 4.014452 | J4: =L4/O4 -> 719.60056 | K4: 6.508 | L4: 17925.25 | M4: 4.52 | N4: =K4-I4 -> 2.493548 | O4: 24.91 | P4: 1.7 | Q4: =K4-P4 -> 4.808 | R4: 96.182 | S4: =(O4*T4)/100 -> 0.891778 | T4: 3.58 | U4: 30917.55 | V4: 30.97 | W4: =U4/V4 -> 998.30643 | X4: =(W4/U4)*100 -> 3.2289312 | Y4: 10024.3 | Z4: 31.62 | AA4: =Y4/Z4 -> 317.02404 | AB4: =(AA4/Y4)*100 -> 3.1625553
A5: 4 | B5: 44567 | C5: 27117001 | D5: =C5/E5 -> 364549.32 | E5: 74.385 | F5: =D5/100000 -> 3.6454932 | G5: =(F5/DataSheet!$C$9*100) -> 115.09891 | H5: =K5/I5 -> 1.609065 | I5: =(J5/L5)*100 -> 4.05515 | J5: =L5/O5 -> 719.62287 | K5: 6.525 | L5: 17745.9 | M5: 4.47 | N5: =K5-I5 -> 2.46985 | O5: 24.66 | P5: 1.728 | Q5: =K5-P5 -> 4.797 | R5: 96.326 | S5: =(O5*T5)/100 -> 0.880362 | T5: 3.57 | U5: 30956.85 | V5: 30.95 | W5: =U5/V5 -> 1000.2213 | X5: =(W5/U5)*100 -> 3.2310178 | Y5: 10034.95 | Z5: 31.66 | AA5: =Y5/Z5 -> 316.95989 | AB5: =(AA5/Y5)*100 -> 3.1585597
A6: 5 | B6: 44568 | C6: 27237049 | D6: =C6/E6 -> 366690.67 | E6: 74.278 | F6: =D6/100000 -> 3.6669067 | G6: =(F6/DataSheet!$C$9*100) -> 115.77499 | H6: =K6/I6 -> 1.619145 | I6: =(J6/L6)*100 -> 4.040404 | J6: =L6/O6 -> 719.70505 | K6: 6.542 | L6: 17812.7 | M6: 4.49 | N6: =K6-I6 -> 2.501596 | O6: 24.75 | P6: 1.765 | Q6: =K6-P6 -> 4.777 | R6: 95.722 | S6: =(O6*T6)/100 -> 0.891 | T6: 3.6 | U6: 31111.55 | V6: 31.06 | W6: =U6/V6 -> 1001.6597 | X6: =(W6/U6)*100 -> 3.219575 | Y6: 10076.6 | Z6: 31.79 | AA6: =Y6/Z6 -> 316.97389 | AB6: =(AA6/Y6)*100 -> 3.1456433
A7: 6 | B7: 44571 | C7: 27464164 | D7: =C7/E7 -> 371012 | E7: 74.025 | F7: =D7/100000 -> 3.71012 | G7: =(F7/DataSheet!$C$9*100) -> 117.13937 | H7: =K7/I7 -> 1.648159 | I7: =(J7/L7)*100 -> 3.9984006 | J7: =L7/O7 -> 719.84406 | K7: 6.59 | L7: 18003.3 | M7: 4.54 | N7: =K7-I7 -> 2.5915994 | O7: 25.01 | P7: 1.755 | Q7: =K7-P7 -> 4.835 | R7: 95.99 | S7: =(O7*T7)/100 -> 0.897859 | T7: 3.59 | U7: 31371.65 | V7: 31.27 | W7: =U7/V7 -> 1003.2507 | X7: =(W7/U7)*100 -> 3.1979533 | Y7: 10218.3 | Z7: 32.28 | AA7: =Y7/Z7 -> 316.55204 | AB7: =(AA7/Y7)*100 -> 3.0978934
A8: 7 | B8: 44572 | C8: 27523206 | D8: =C8/E8 -> 372857.28 | E8: 73.817 | F8: =D8/100000 -> 3.7285728 | G8: =(F8/DataSheet!$C$9*100) -> 117.72197 | H8: =K8/I8 -> 1.648413 | I8: =(J8/L8)*100 -> 3.9856517 | J8: =L8/O8 -> 719.6393 | K8: 6.57 | L8: 18055.75 | M8: 4.55 | N8: =K8-I8 -> 2.5843483 | O8: 25.09 | P8: 1.746 | Q8: =K8-P8 -> 4.824 | R8: 95.625 | S8: =(O8*T8)/100 -> 0.898222 | T8: 3.58 | U8: 31400.4 | V8: 31.32 | W8: =U8/V8 -> 1002.567 | X8: =(W8/U8)*100 -> 3.192848 | Y8: 10228.8 | Z8: 32.31 | AA8: =Y8/Z8 -> 316.5831 | AB8: =(AA8/Y8)*100 -> 3.095017
A9: 8 | B9: 44573 | C9: 27726856 | D9: =C9/E9 -> 375717.93 | E9: 73.797 | F9: =D9/100000 -> 3.7571793 | G9: =(F9/DataSheet!$C$9*100) -> 118.62517 | H9: =K9/I9 -> 1.668029 | I9: =(J9/L9)*100 -> 3.9525692 | J9: =L9/O9 -> 719.85573 | K9: 6.593 | L9: 18212.35 | M9: 4.59 | N9: =K9-I9 -> 2.6404308 | O9: 25.3 | P9: 1.752 | Q9: =K9-P9 -> 4.841 | R9: 94.901 | S9: =(O9*T9)/100 -> 0.90321 | T9: 3.57 | U9: 31791.55 | V9: 31.69 | W9: =U9/V9 -> 1003.2045 | X9: =(W9/U9)*100 -> 3.1555696 | Y9: 10292.35 | Z9: 32.51 | AA9: =Y9/Z9 -> 316.59028 | AB9: =(AA9/Y9)*100 -> 3.0759766
A10: 9 | B10: 44574 | C10: 27818875 | D10: =C10/E10 -> 376073.04 | E10: 73.972 | F10: =D10/100000 -> 3.7607304 | G10: =(F10/DataSheet!$C$9*100) -> 118.73729 | H10: =K10/I10 -> 1.6645257 | I10: =(J10/L10)*100 -> 3.9416634 | J10: =L10/O10 -> 719.66102 | K10: 6.561 | L10: 18257.8 | M10: 4.6 | N10: =K10-I10 -> 2.6193366 | O10: 25.37 | P10: 1.701 | Q10: =K10-P10 -> 4.86 | R10: 94.775 | S10: =(O10*T10)/100 -> 0.908246 | T10: 3.58 | U10: 31997.2 | V10: 31.85 | W10: =U10/V10 -> 1004.6217 | X10: =(W10/U10)*100 -> 3.1397174 | Y10: 10352.6 | Z10: 32.64 | AA10: =Y10/Z10 -> 317.17525 | AB10: =(AA10/Y10)*100 -> 3.0637255
A11: 10 | B11: 44575 | C11: 27857090 | D11: =C11/E11 -> 375655.24 | E11: 74.156 | F11: =D11/100000 -> 3.7565524 | G11: =(F11/DataSheet!$C$9*100) -> 118.60537 | H11: =K11/I11 -> 1.665246 | I11: =(J11/L11)*100 -> 3.9525692 | J11: =L11/O11 -> 721.57115 | K11: 6.582 | L11: 18255.75 | M11: 4.6 | N11: =K11-I11 -> 2.6294308 | O11: 25.3 | P11: 1.793 | Q11: =K11-P11 -> 4.789 | R11: 95.161 | S11: =(O11*T11)/100 -> 0.90827 | T11: 3.59 | U11: 31989.65 | V11: 31.84 | W11: =U11/V11 -> 1004.7001 | X11: =(W11/U11)*100 -> 3.1407035 | Y11: 10424 | Z11: 32.87 | AA11: =Y11/Z11 -> 317.12808 | AB11: =(AA11/Y11)*100 -> 3.0422878
A12: 11 | B12: 44578 | C12: 28010582 | D12: =C12/E12 -> 377221.49 | E12: 74.255 | F12: =D12/100000 -> 3.7722149 | G12: =(F12/DataSheet!$C$9*100) -> 119.09988 | H12: =K12/I12 -> 1.6835532 | I12: =(J12/L12)*100 -> 3.9416634 | J12: =L12/O12 -> 721.64367 | K12: 6.636 | L12: 18308.1 | M12: 4.61 | N12: =K12-I12 -> 2.6943366 | O12: 25.37 | P12: 1.809 | Q12: =K12-P12 -> 4.827 | R12: 95.161 | S12: =(O12*T12)/100 -> 0.91332 | T12: 3.6 | U12: 32040.6 | V12: 31.92 | W12: =U12/V12 -> 1003.7782 | X12: =(W12/U12)*100 -> 3.1328321 | Y12: 10471.85 | Z12: 33.01 | AA12: =Y12/Z12 -> 317.23266 | AB12: =(AA12/Y12)*100 -> 3.029385
A13: 12 | B13: 44579 | C13: 27634598 | D13: =C13/E13 -> 370610.85 | E13: 74.565 | F13: =D13/100000 -> 3.7061085 | G13: =(F13/DataSheet!$C$9*100) -> 117.01271 | H13: =K13/I13 -> 1.65675 | I13: =(J13/L13)*100 -> 4 | J13: =L13/O13 -> 724.522 | K13: 6.627 | L13: 18113.05 | M13: 4.56 | N13: =K13-I13 -> 2.627 | O13: 25 | P13: 1.875 | Q13: =K13-P13 -> 4.752 | R13: 95.723 | S13: =(O13*T13)/100 -> 0.9 | T13: 3.6 | U13: 31381.45 | V13: 31.32 | W13: =U13/V13 -> 1001.962 | X13: =(W13/U13)*100 -> 3.192848 | Y13: 10257.8 | Z13: 32.34 | AA13: =Y13/Z13 -> 317.18615 | AB13: =(AA13/Y13)*100 -> 3.0921459
... A249: 248 | B249: 44925 | C249: 28323372 | D249: =C249/E249 -> 342441.93 | E249: 82.71 | F249: =D249/100000 -> 3.4244193 | G249: =(F249/DataSheet!$C$9*100) -> 108.11896 | H249: =K249/I249 -> 1.595028 | I249: =(J249/L249)*100 -> 4.5892611 | J249: =L249/O249 -> 830.8995 | K249: 7.32 | L249: 18105.3 | M249: 4.25 | N249: =K249-I249 -> 2.7307389 | O249: 21.79 | P249: 3.87 | Q249: =K249-P249 -> 3.45 | R249: 103.26 | S249: =(O249*T249)/100 -> 1.381486 | T249: 6.34 | U249: 11885.75 | V249: 26.12 | W249: =U249/V249 -> 455.04403 | X249: =(W249/U249)*100 -> 3.8284839 | Y249: 9481.25 | Z249: 19.04 | AA249: =Y249/Z249 -> 497.96481 | AB249: =(AA249/Y249)*100 -> 5.2521008
A250: 249 | B250: 44928 | C250: 28454959 | D250: =C250/E250 -> 343908.14 | E250: 82.74 | F250: =D250/100000 -> 3.4390814 | G250: =(F250/DataSheet!$C$10*100) -> 102.77849 | H250: =K250/I250 -> 1.60746 | I250: =(J250/L250)*100 -> 4.56621 | J250: =L250/O250 -> 830.93379 | K250: 7.34 | L250: 18197.45 | M250: 4.27 | N250: =K250-I250 -> 2.77379 | O250: 21.9 | P250: 3.87 | Q250: =K250-P250 -> 3.47 | R250: 104.41 | S250: =(O250*T250)/100 -> 1.37751 | T250: 6.29 | U250: 11970.3 | V250: 26.31 | W250: =U250/V250 -> 454.97149 | X250: =(W250/U250)*100 -> 3.8008362 | Y250: 9552.8 | Z250: 19.18 | AA250: =Y250/Z250 -> 498.06048 | AB250: =(AA250/Y250)*100 -> 5.2137643
A251: 250 | B251: 44929 | C251: 28548826 | D251: =C251/E251 -> 344917.55 | E251: 82.77 | F251: =D251/100000 -> 3.4491755 | G251: =(F251/DataSheet!$C$10*100) -> 103.08016 | H251: =K251/I251 -> 1.606008 | I251: =(J251/L251)*100 -> 4.5578851 | J251: =L251/O251 -> 831.01869 | K251: 7.32 | L251: 18232.55 | M251: 4.28 | N251: =K251-I251 -> 2.7621149 | O251: 21.94 | P251: 3.75 | Q251: =K251-P251 -> 3.57 | R251: 104.31 | S251: =(O251*T251)/100 -> 1.38222 | T251: 6.3 | U251: 11994.4 | V251: 26.36 | W251: =U251/V251 -> 455.02276 | X251: =(W251/U251)*100 -> 3.7936267 | Y251: 9566.55 | Z251: 19.21 | AA251: =Y251/Z251 -> 497.99844 | AB251: =(AA251/Y251)*100 -> 5.2056221
A252: 251 | B252: 44930 | C252: 28257666 | D252: =C252/E252 -> 341936.91 | E252: 82.64 | F252: =D252/100000 -> 3.4193691 | G252: =(F252/DataSheet!$C$10*100) -> 102.18938 | H252: =K252/I252 -> 1.589172 | I252: =(J252/L252)*100 -> 4.6061723 | J252: =L252/O252 -> 831.08936 | K252: 7.32 | L252: 18042.95 | M252: 4.23 | N252: =K252-I252 -> 2.7138277 | O252: 21.71 | P252: 3.69 | Q252: =K252-P252 -> 3.63 | R252: 104.02 | S252: =(O252*T252)/100 -> 1.380756 | T252: 6.36 | U252: 11886.95 | V252: 26.12 | W252: =U252/V252 -> 455.08997 | X252: =(W252/U252)*100 -> 3.8284839 | Y252: 9480.9 | Z252: 19.04 | AA252: =Y252/Z252 -> 497.94643 | AB252: =(AA252/Y252)*100 -> 5.2521008
A253: 252 | B253: 44931 | C253: 28279706 | D253: =C253/E253 -> 342535.19 | E253: 82.56 | F253: =D253/100000 -> 3.4253519 | G253: =(F253/DataSheet!$C$10*100) -> 102.36818 | H253: =K253/I253 -> 1.58478 | I253: =(J253/L253)*100 -> 4.6189376 | J253: =L253/O253 -> 831.04619 | K253: 7.32 | L253: 17992.15 | M253: 4.22 | N253: =K253-I253 -> 2.7010624 | O253: 21.65 | P253: 3.72 | Q253: =K253-P253 -> 3.6 | R253: 104.82 | S253: =(O253*T253)/100 -> 1.379105 | T253: 6.37 | U253: 11932.85 | V253: 26.22 | W253: =U253/V253 -> 455.10488 | X253: =(W253/U253)*100 -> 3.8138825 | Y253: 9479.5 | Z253: 19.03 | AA253: =Y253/Z253 -> 498.13452 | AB253: =(AA253/Y253)*100 -> 5.2548607
A254: 253 | B254: 44932 | C254: 28057696 | D254: =C254/E254 -> 341044.08 | E254: 82.27 | F254: =D254/100000 -> 3.4104408 | G254: =(F254/DataSheet!$C$10*100) -> 101.92255 | H254: =K254/I254 -> 1.583813 | I254: =(J254/L254)*100 -> 4.6533271 | J254: =L254/O254 -> 831.05863 | K254: 7.37 | L254: 17859.45 | M254: 4.19 | N254: =K254-I254 -> 2.7166729 | O254: 21.49 | P254: 3.56 | Q254: =K254-P254 -> 3.81 | R254: 103.64 | S254: =(O254*T254)/100 -> 1.368913 | T254: 6.37 | U254: 11850.6 | V254: 26.04 | W254: =U254/V254 -> 455.09217 | X254: =(W254/U254)*100 -> 3.8402458 | Y254: 9406.75 | Z254: 18.89 | AA254: =Y254/Z254 -> 497.97512 | AB254: =(AA254/Y254)*100 -> 5.2938062
A255: 254 | B255: 44935 | C255: 28374278 | D255: =C255/E255 -> 345311.89 | E255: 82.17 | F255: =D255/100000 -> 3.4531189 | G255: =(F255/DataSheet!$C$10*100) -> 103.19801 | H255: =K255/I255 -> 1.598652 | I255: =(J255/L255)*100 -> 4.5913682 | J255: =L255/O255 -> 831.09275 | K255: 7.34 | L255: 18101.2 | M255: 4.25 | N255: =K255-I255 -> 2.7486318 | O255: 21.78 | P255: 3.52 | Q255: =K255-P255 -> 3.82 | R255: 102.73 | S255: =(O255*T255)/100 -> 1.389564 | T255: 6.38 | U255: 11948.9 | V255: 26.26 | W255: =U255/V255 -> 455.02285 | X255: =(W255/U255)*100 -> 3.8080731 | Y255: 9444.15 | Z255: 18.96 | AA255: =Y255/Z255 -> 498.10918 | AB255: =(AA255/Y255)*100 -> 5.2742616
A256: 255 | B256: 44936 | C256: 28164222 | D256: =C256/E256 -> 345149.78 | E256: 81.6 | F256: =D256/100000 -> 3.4514978 | G256: =(F256/DataSheet!$C$10*100) -> 103.14956 | H256: =K256/I256 -> 1.576036 | I256: =(J256/L256)*100 -> 4.6382189 | J256: =L256/O256 -> 830.8975 | K256: 7.31 | L256: 17914.15 | M256: 4.2 | N256: =K256-I256 -> 2.6717811 | O256: 21.56 | P256: 3.61 | Q256: =K256-P256 -> 3.7 | R256: 102.98 | S256: =(O256*T256)/100 -> 1.375528 | T256: 6.38 | U256: 11899.55 | V256: 26.15 | W256: =U256/V256 -> 455.04971 | X256: =(W256/U256)*100 -> 3.8240918 | Y256: 9398 | Z256: 18.87 | AA256: =Y256/Z256 -> 498.03922 | AB256: =(AA256/Y256)*100 -> 5.2994171
A257: 256 | B257: 44937 | C257: 28116864 | D257: =C257/E257 -> 344442.78 | E257: 81.63 | F257: =D257/100000 -> 3.4444278 | G257: =(F257/DataSheet!$C$10*100) -> 102.93827 | H257: =K257/I257 -> 1.568808 | I257: =(J257/L257)*100 -> 4.6468401 | J257: =L257/O257 -> 831.58457 | K257: 7.29 | L257: 17895.7 | M257: 4.2 | N257: =K257-I257 -> 2.6431599 | O257: 21.52 | P257: 3.54 | Q257: =K257-P257 -> 3.75 | R257: 102.92 | S257: =(O257*T257)/100 -> 1.37728 | T257: 6.4 | U257: 11862.85 | V257: 26.07 | W257: =U257/V257 -> 455.03836 | X257: =(W257/U257)*100 -> 3.8358266 | Y257: 9403.2 | Z257: 18.88 | AA257: =Y257/Z257 -> 498.05085 | AB257: =(AA257/Y257)*100 -> 5.2966102
A258: 257 | B258: 44938 | C258: 28079395 | D258: =C258/E258 -> 346231.75 | E258: 81.1 | F258: =D258/100000 -> 3.4623175 | G258: =(F258/DataSheet!$C$10*100) -> 103.47291 | H258: =K258/I258 -> 1.563016 | I258: =(J258/L258)*100 -> 4.6576619 | J258: =L258/O258 -> 831.77457 | K258: 7.28 | L258: 17858.2 | M258: 4.19 | N258: =K258-I258 -> 2.6223381 | O258: 21.47 | P258: 3.44 | Q258: =K258-P258 -> 3.84 | R258: 101.99 | S258: =(O258*T258)/100 -> 1.378374 | T258: 6.42 | U258: 11836.4 | V258: 26.01 | W258: =U258/V258 -> 455.07113 | X258: =(W258/U258)*100 -> 3.8446751 | Y258: 9409.4 | Z258: 18.89 | AA258: =Y258/Z258 -> 498.1154 | AB258: =(AA258/Y258)*100 -> 5.2938062
A259: 258 | B259: 44939 | C259: 28213564 | D259: =C259/E259 -> 347115.7 | E259: 81.28 | F259: =D259/100000 -> 3.471157 | G259: =(F259/DataSheet!$C$10*100) -> 103.73709 | H259: =K259/I259 -> 1.570266 | I259: =(J259/L259)*100 -> 4.6425255 | J259: =L259/O259 -> 833.63974 | K259: 7.29 | L259: 17956.6 | M259: 4.21 | N259: =K259-I259 -> 2.6474745 | O259: 21.54 | P259: 3.49 | Q259: =K259-P259 -> 3.8 | R259: 101.94 | S259: =(O259*T259)/100 -> 1.382868 | T259: 6.42 | U259: 11830.4 | V259: 26 | W259: =U259/V259 -> 455.01538 | X259: =(W259/U259)*100 -> 3.8461538 | Y259: 9436.25 | Z259: 18.94 | AA259: =Y259/Z259 -> 498.21806 | AB259: =(AA259/Y259)*100 -> 5.279831
A260: 259 | B260: 44942 | C260: 28147293 | D260: =C260/E260 -> 344857.79 | E260: 81.62 | F260: =D260/100000 -> 3.4485779 | G260: =(F260/DataSheet!$C$10*100) -> 103.0623 | H260: =K260/I260 -> 1.562088 | I260: =(J260/L260)*100 -> 4.6860356 | J260: =L260/O260 -> 838.55904 | K260: 7.32 | L260: 17894.85 | M260: 4.19 | N260: =K260-I260 -> 2.6339644 | O260: 21.34 | P260: 3.52 | Q260: =K260-P260 -> 3.8 | R260: 101.94 | S260: =(O260*T260)/100 -> 1.372162 | T260: 6.43 | U260: 11800.3 | V260: 26.16 | W260: =U260/V260 -> 451.0818 | X260: =(W260/U260)*100 -> 3.82263 | Y260: 9431.25 | Z260: 18.93 | AA260: =Y260/Z260 -> 498.21712 | AB260: =(AA260/Y260)*100 -> 5.2826202
A261: 260 | B261: 44943 | C261: 28272805 | D261: =C261/E261 -> 346353.11 | E261: 81.63 | F261: =D261/100000 -> 3.4635311 | G261: =(F261/DataSheet!$C$10*100) -> 103.50918 | H261: =K261/I261 -> 1.578149 | I261: =(J261/L261)*100 -> 4.6446818 | J261: =L261/O261 -> 838.51835 | K261: 7.33 | L261: 18053.3 | M261: 4.23 | N261: =K261-I261 -> 2.6853182 | O261: 21.53 | P261: 3.54 | Q261: =K261-P261 -> 3.79 | R261: 102.14 | S261: =(O261*T261)/100 -> 1.384379 | T261: 6.43 | U261: 11793.6 | V261: 26.03 | W261: =U261/V261 -> 453.07722 | X261: =(W261/U261)*100 -> 3.8417211 | Y261: 9417.95 | Z261: 18.87 | AA261: =Y261/Z261 -> 499.09645 | AB261: =(AA261/Y261)*100 -> 5.2994171
... A495: 494 | B495: 45289 | C495: 36937726 | D495: =C495/E495 -> 444016.42 | E495: 83.19 | F495: =D495/100000 -> 4.4401642 | G495: =(F495/DataSheet!$C$10*100) -> 132.6963 | H495: =K495/I495 -> 1.661289 | I495: =(J495/L495)*100 -> 4.3159258 | J495: =L495/O495 -> 937.91109 | K495: 7.17 | L495: 21731.4 | M495: 3.81 | N495: =K495-I495 -> 2.8540742 | O495: 23.17 | P495: 3.86 | Q495: =K495-P495 -> 3.31 | R495: 101.02 | S495: =(O495*T495)/100 -> 1.59873 | T495: 6.9 | U495: 17077.05 | V495: 26.51 | W495: =U495/V495 -> 644.1739 | X495: =(W495/U495)*100 -> 3.7721614 | Y495: 14041.3 | Z495: 27.37 | AA495: =Y495/Z495 -> 513.0179 | AB495: =(AA495/Y495)*100 -> 3.6536354
A496: 495 | B496: 45292 | C496: 37094900 | D496: =C496/E496 -> 445691.46 | E496: 83.23 | F496: =D496/100000 -> 4.4569146 | G496: =(F496/DataSheet!$C$11*100) -> 122.49352 | H496: =K496/I496 -> 1.666642 | I496: =(J496/L496)*100 -> 4.3140638 | J496: =L496/O496 -> 937.95945 | K496: 7.19 | L496: 21741.9 | M496: 3.81 | N496: =K496-I496 -> 2.8759362 | O496: 23.18 | P496: 3.89 | Q496: =K496-P496 -> 3.3 | R496: 101.02 | S496: =(O496*T496)/100 -> 1.608692 | T496: 6.94 | U496: 17174 | V496: 26.66 | W496: =U496/V496 -> 644.18605 | X496: =(W496/U496)*100 -> 3.7509377 | Y496: 14129.7 | Z496: 27.54 | AA496: =Y496/Z496 -> 513.061 | AB496: =(AA496/Y496)*100 -> 3.6310821
A497: 496 | B497: 45293 | C497: 37029724 | D497: =C497/E497 -> 444694.65 | E497: 83.27 | F497: =D497/100000 -> 4.4469465 | G497: =(F497/DataSheet!$C$11*100) -> 122.21956 | H497: =K497/I497 -> 1.6632 | I497: =(J497/L497)*100 -> 4.3290043 | J497: =L497/O497 -> 937.91342 | K497: 7.2 | L497: 21665.8 | M497: 3.79 | N497: =K497-I497 -> 2.8709957 | O497: 23.1 | P497: 3.94 | Q497: =K497-P497 -> 3.26 | R497: 101.89 | S497: =(O497*T497)/100 -> 1.60083 | T497: 6.93 | U497: 17148.1 | V497: 26.62 | W497: =U497/V497 -> 644.18107 | X497: =(W497/U497)*100 -> 3.756574 | Y497: 14124.25 | Z497: 27.53 | AA497: =Y497/Z497 -> 513.0494 | AB497: =(AA497/Y497)*100 -> 3.632401
A498: 497 | B498: 45294 | C498: 37019529 | D498: =C498/E498 -> 444518.84 | E498: 83.28 | F498: =D498/100000 -> 4.4451884 | G498: =(F498/DataSheet!$C$11*100) -> 122.17124 | H498: =K498/I498 -> 1.653974 | I498: =(J498/L498)*100 -> 4.3591979 | J498: =L498/O498 -> 937.98387 | K498: 7.21 | L498: 21517.35 | M498: 3.77 | N498: =K498-I498 -> 2.8508021 | O498: 22.94 | P498: 3.92 | Q498: =K498-P498 -> 3.29 | R498: 102.19 | S498: =(O498*T498)/100 -> 1.589742 | T498: 6.93 | U498: 17189.95 | V498: 26.68 | W498: =U498/V498 -> 644.30097 | X498: =(W498/U498)*100 -> 3.7481259 | Y498: 14141 | Z498: 27.57 | AA498: =Y498/Z498 -> 512.91259 | AB498: =(AA498/Y498)*100 -> 3.6271309
A499: 498 | B499: 45295 | C499: 37346699 | D499: =C499/E499 -> 448662.89 | E499: 83.24 | F499: =D499/100000 -> 4.4866289 | G499: =(F499/DataSheet!$C$11*100) -> 123.31019 | H499: =K499/I499 -> 1.667098 | I499: =(J499/L499)*100 -> 4.3308792 | J499: =L499/O499 -> 938.0078 | K499: 7.22 | L499: 21658.6 | M499: 3.79 | N499: =K499-I499 -> 2.8891208 | O499: 23.09 | P499: 4 | Q499: =K499-P499 -> 3.22 | R499: 102.13 | S499: =(O499*T499)/100 -> 1.607064 | T499: 6.96 | U499: 17443.75 | V499: 27.07 | W499: =U499/V499 -> 644.39416 | X499: =(W499/U499)*100 -> 3.6941263 | Y499: 14286.3 | Z499: 27.85 | AA499: =Y499/Z499 -> 512.97307 | AB499: =(AA499/Y499)*100 -> 3.5906643
A500: 499 | B500: 45296 | C500: 37448192 | D500: =C500/E500 -> 450640.1 | E500: 83.1 | F500: =D500/100000 -> 4.506401 | G500: =(F500/DataSheet!$C$11*100) -> 123.8536 | H500: =K500/I500 -> 1.673745 | I500: =(J500/L500)*100 -> 4.3196544 | J500: =L500/O500 -> 937.83153 | K500: 7.23 | L500: 21710.8 | M500: 3.8 | N500: =K500-I500 -> 2.9103456 | O500: 23.15 | P500: 4.05 | Q500: =K500-P500 -> 3.18 | R500: 102.12 | S500: =(O500*T500)/100 -> 1.604295 | T500: 6.93 | U500: 17499.65 | V500: 27.16 | W500: =U500/V500 -> 644.31701 | X500: =(W500/U500)*100 -> 3.6818851 | Y500: 14382.4 | Z500: 28.04 | AA500: =Y500/Z500 -> 512.92439 | AB500: =(AA500/Y500)*100 -> 3.5663338
A501: 500 | B501: 45299 | C501: 37150869 | D501: =C501/E501 -> 447385.22 | E501: 83.04 | F501: =D501/100000 -> 4.4738522 | G501: =(F501/DataSheet!$C$11*100) -> 122.95903 | H501: =K501/I501 -> 1.65168 | I501: =(J501/L501)*100 -> 4.3591979 | J501: =L501/O501 -> 937.79425 | K501: 7.2 | L501: 21513 | M501: 3.77 | N501: =K501-I501 -> 2.8408021 | O501: 22.94 | P501: 4.02 | Q501: =K501-P501 -> 3.18 | R501: 101.92 | S501: =(O501*T501)/100 -> 1.59433 | T501: 6.95 | U501: 17350.55 | V501: 26.93 | W501: =U501/V501 -> 644.28333 | X501: =(W501/U501)*100 -> 3.7133309 | Y501: 14298.2 | Z501: 27.87 | AA501: =Y501/Z501 -> 513.03193 | AB501: =(AA501/Y501)*100 -> 3.5880875
A502: 501 | B502: 45300 | C502: 37265203 | D502: =C502/E502 -> 448438.06 | E502: 83.1 | F502: =D502/100000 -> 4.4843806 | G502: =(F502/DataSheet!$C$11*100) -> 123.2484 | H502: =K502/I502 -> 1.649246 | I502: =(J502/L502)*100 -> 4.3535046 | J502: =L502/O502 -> 937.95603 | K502: 7.18 | L502: 21544.85 | M502: 3.77 | N502: =K502-I502 -> 2.8264954 | O502: 22.97 | P502: 4.01 | Q502: =K502-P502 -> 3.17 | R502: 102.28 | S502: =(O502*T502)/100 -> 1.598712 | T502: 6.96 | U502: 17382 | V502: 26.98 | W502: =U502/V502 -> 644.255 | X502: =(W502/U502)*100 -> 3.7064492 | Y502: 14350.9 | Z502: 27.97 | AA502: =Y502/Z502 -> 513.08187 | AB502: =(AA502/Y502)*100 -> 3.5752592
A503: 502 | B503: 45301 | C503: 37392677 | D503: =C503/E503 -> 450405.65 | E503: 83.02 | F503: =D503/100000 -> 4.5040565 | G503: =(F503/DataSheet!$C$11*100) -> 123.78917 | H503: =K503/I503 -> 1.652685 | I503: =(J503/L503)*100 -> 4.3383948 | J503: =L503/O503 -> 937.90456 | K503: 7.17 | L503: 21618.7 | M503: 3.79 | N503: =K503-I503 -> 2.8316052 | O503: 23.05 | P503: 4.03 | Q503: =K503-P503 -> 3.14 | R503: 102.08 | S503: =(O503*T503)/100 -> 1.60428 | T503: 6.96 | U503: 17425.35 | V503: 27.05 | W503: =U503/V503 -> 644.19039 | X503: =(W503/U503)*100 -> 3.6968577 | Y503: 14379.85 | Z503: 28.03 | AA503: =Y503/Z503 -> 513.01641 | AB503: =(AA503/Y503)*100 -> 3.5676061
A504: 503 | B504: 45302 | C504: 37565219 | D504: =C504/E504 -> 452266.06 | E504: 83.06 | F504: =D504/100000 -> 4.5226606 | G504: =(F504/DataSheet!$C$11*100) -> 124.30048 | H504: =K504/I504 -> 1.652528 | I504: =(J504/L504)*100 -> 4.3327556 | J504: =L504/O504 -> 937.92028 | K504: 7.16 | L504: 21647.2 | M504: 3.79 | N504: =K504-I504 -> 2.8272444 | O504: 23.08 | P504: 3.97 | Q504: =K504-P504 -> 3.19 | R504: 102.02 | S504: =(O504*T504)/100 -> 1.60406 | T504: 6.95 | U504: 17500.5 | V504: 27.16 | W504: =U504/V504 -> 644.34831 | X504: =(W504/U504)*100 -> 3.6818851 | Y504: 14498.55 | Z504: 28.28 | AA504: =Y504/Z504 -> 512.67857 | AB504: =(AA504/Y504)*100 -> 3.5360679
A505: 504 | B505: 45303 | C505: 37846544 | D505: =C505/E505 -> 456808.02 | E505: 82.85 | F505: =D505/100000 -> 4.5680802 | G505: =(F505/DataSheet!$C$11*100) -> 125.54879 | H505: =K505/I505 -> 1.673478 | I505: =(J505/L505)*100 -> 4.2844901 | J505: =L505/O505 -> 938.06984 | K505: 7.17 | L505: 21894.55 | M505: 3.83 | N505: =K505-I505 -> 2.8855099 | O505: 23.34 | P505: 3.93 | Q505: =K505-P505 -> 3.24 | R505: 102.15 | S505: =(O505*T505)/100 -> 1.62213 | T505: 6.95 | U505: 17563.85 | V505: 27.26 | W505: =U505/V505 -> 644.30851 | X505: =(W505/U505)*100 -> 3.6683786 | Y505: 14552.75 | Z505: 28.39 | AA505: =Y505/Z505 -> 512.60127 | AB505: =(AA505/Y505)*100 -> 3.522367
A506: 505 | B506: 45306 | C506: 38129439 | D506: =C506/E506 -> 460389.27 | E506: 82.82 | F506: =D506/100000 -> 4.6038927 | G506: =(F506/DataSheet!$C$11*100) -> 126.53306 | H506: =K506/I506 -> 1.684326 | I506: =(J506/L506)*100 -> 4.2390844 | J506: =L506/O506 -> 936.72955 | K506: 7.14 | L506: 22097.45 | M506: 3.87 | N506: =K506-I506 -> 2.9009156 | O506: 23.59 | P506: 3.98 | Q506: =K506-P506 -> 3.16 | R506: 102.15 | S506: =(O506*T506)/100 -> 1.639505 | T506: 6.95 | U506: 17656.35 | V506: 27.39 | W506: =U506/V506 -> 644.6276 | X506: =(W506/U506)*100 -> 3.6509675 | Y506: 14589 | Z506: 28.45 | AA506: =Y506/Z506 -> 512.79438 | AB506: =(AA506/Y506)*100 -> 3.5149385
A507: 506 | B507: 45307 | C507: 38021747 | D507: =C507/E507 -> 457652.23 | E507: 83.08 | F507: =D507/100000 -> 4.5765223 | G507: =(F507/DataSheet!$C$11*100) -> 125.78081 | H507: =K507/I507 -> 1.679328 | I507: =(J507/L507)*100 -> 4.2517007 | J507: =L507/O507 -> 936.74745 | K507: 7.14 | L507: 22032.3 | M507: 3.86 | N507: =K507-I507 -> 2.8882993 | O507: 23.52 | P507: 4.05 | Q507: =K507-P507 -> 3.09 | R507: 103.11 | S507: =(O507*T507)/100 -> 1.639344 | T507: 6.97 | U507: 17599.8 | V507: 27.3 | W507: =U507/V507 -> 644.68132 | X507: =(W507/U507)*100 -> 3.6630037 | Y507: 14549.05 | Z507: 28.37 | AA507: =Y507/Z507 -> 512.83222 | AB507: =(AA507/Y507)*100 -> 3.5248502
... A744: 743 | B744: 45657 | C744: 44347671 | D744: =C744/E744 -> 518358.82 | E744: 85.554 | F744: =D744/100000 -> 5.1835882 | G744: =(F744/DataSheet!$C$11*100) -> 142.46537 | H744: =K744/I744 -> 1.4727861 | I744: =(J744/L744)*100 -> 4.5892611 | J744: =L744/O744 -> 1085.1216 | K744: 6.759 | L744: 23644.8 | M744: 3.53 | N744: =K744-I744 -> 2.1697389 | O744: 21.79 | P744: 4.572 | Q744: =K744-P744 -> 2.187 | R744: 108.296 | S744: =(O744*T744)/100 -> 1.433782 | T744: 6.58 | U744: 21141.2 | V744: 43.3 | W744: =U744/V744 -> 488.24942 | X744: =(W744/U744)*100 -> 2.3094688 | Y744: 17752.25 | Z744: 34.39 | AA744: =Y744/Z744 -> 516.20384 | AB744: =(AA744/Y744)*100 -> 2.907822
...

Sheet Mid vs Small Yield

Sheet Dollar Index

Sheet Indian Bond Vs USA Bond 10 Year

Sheet Currency Vs Market Cap

Sheet Yield in Short term & Long term

Sheet Beer Ratio

Sheet Nifty Earning Yield

Sheet CHART Market Cap to GDP

Sheet Marketcap
A1: S.no | B1: Date | C1: Market Cap | D1: US $ | E1: USD/INR | F1: Trillion | G1: Market Cap to GDP | H1: BEER | I1: Nifty 50 Earning Yield | J1: NIFTY 50 EPS | K1: India 10Yr Yield | L1: Nifty 50 | M1: Price to Book | N1: Yield Gap | O1: Nifty 50 pe | P1: US 10yr Bond | Q1: India yr- US 10yr | R1: Dollar index | S1: PREITY Ratio | T1: 91 day T Bill | U1: Nifty Midcap 150 | V1: Midcap 150 PE | W1: Midcap EPS | X1: Midcap Earning Yield | Y1: Nifty Smallcap 250 | Z1: Smallcap 250 PE | AA1: Smallcap EPS | AB1: Smallcap Earning Yield
